<robot name="myfirst">
  <material name="blue">
    <color rgba="0 0 0.8 1"/>
  </material>
  <material name="black">
    <color rgba="0 0 0 1"/>
  </material>

  <link name="base_link">
    <visual>
      <geometry>
        <cylinder length="0.081" radius="0.05"/>
      </geometry>
      <material name="black"/>
    </visual>
  </link>

  <link name="stroke">
    <visual>
      <geometry>
        <cylinder length="0.038" radius="0.025"/>
      </geometry>
      <material name="blue"/>
    </visual>
  </link>

  <joint name="base_to_stroke" type="prismatic">
    <parent link="base_link"/>
    <child link="stroke"/>
    <origin xyz="0 0 0.0255"/> <!-- start 8mm above base -->
    <axis xyz="0 0 1"/>
    <limit effort="1000.0" lower="0" upper="0.034" velocity="0.5"/>
  </joint>
</robot>
